Workbook

Sheet booking
A1: booking_id | B1: user_id | C1: display_name | D1: field_no | E1: date | F1: time_from | G1: time_to | H1: duration_h | I1: crosses_18 | J1: price_total_thb | K1: status | L1: hold_expires_at | M1: created_at | N1: updated_at | O1: confirmed_by | P1: cancelled_by | Q1: cancel_reason | R1: paid_at | S1: version | T1: start_ts | U1: end_ts | V1: timeout_notified | W1: notes | X1: admin_note
A2: BK001 | B2: U2025102998427bb1d2b645e6a3aaadd6 | C2: win | D2: 4 | E2: 45962 | F2: 0.83333333 | G2: 0.875 | J2: 1000 | K2: CONFIRMED | L2: 2025-11-01T11:10:00+07:00 | N2: 2025-11-01T08:54:52+0700 | O2: U2025102998427bb1d2b645e6a3aaadd6 | S2: 5 | T2: 2025-11-01T20:00:00+07:00 | U2: 2025-11-01T21:00:00+07:00

Sheet user_state
A1: user_id | B1: date | C1: time_from | D1: duration_h | E1: field_no | F1: updated_at
A2: U2025102998427bb1d2b645e6a3aaadd6 | B2: 2025-12-10 | C2: 18:00 | D2: 1 | E2: 5 | F2: 2025-12-10 10:28:55
A3: U6ac2fcd8621eb1d87be14f636213eb2f | B3: 2025-11-29 | C3: 17:00 | D3: 1 | E3: 5 | F3: 2025-11-29 17:15:44
A4: U03b32d0823ff8bb61a3cddc2186ebd53 | B4: 2025-11-29 | C4: 21:00 | E4: 6 | F4: 2025-11-29 12:55:18
A5: Ua636ab14081b483636896549d2026398 | B5: 2026-01-13 | C5: 18:00 | D5: 1 | E5: 4 | F5: 2026-01-13 09:33:10
A6: Uf5d3d661f3d0a7150a814471e1a3adad | B6: 2025-12-17 | C6: 17:00 | D6: 1 | E6: 4 | F6: 2025-12-17 10:51:12

Sheet log
A1: ts | B1: user_id | C1: action | D1: patch
A2: 46015.408 | B2: Ua636ab14081b483636896549d2026398 | C2: saveUserState_ | D2: {"date":"2025-12-24"}
A3: 46015.408 | B3: Ua636ab14081b483636896549d2026398 | C3: saveUserState_ | D3: {"time_from":"18:00"}
A4: 46015.408 | B4: Ua636ab14081b483636896549d2026398 | C4: saveUserState_ | D4: {"field_no":"3"}
A5: 46015.42 | B5: Ua636ab14081b483636896549d2026398 | C5: saveUserState_ | D5: {"time_from":"16:00"}
A6: 46015.42 | B6: Ua636ab14081b483636896549d2026398 | C6: saveUserState_ | D6: {"field_no":"1"}
A7: 46025.544 | B7: Ua636ab14081b483636896549d2026398 | C7: saveUserState_ | D7: {"date":"2026-01-03"}
A8: 46025.544 | B8: Ua636ab14081b483636896549d2026398 | C8: saveUserState_ | D8: {"time_from":"17:00"}
A9: 46035.398 | B9: Ua636ab14081b483636896549d2026398 | C9: saveUserState_ | D9: {"date":"2026-01-13"}
A10: 46035.398 | B10: Ua636ab14081b483636896549d2026398 | C10: saveUserState_ | D10: {"time_from":"18:00"}
A11: 46035.398 | B11: Ua636ab14081b483636896549d2026398 | C11: saveUserState_ | D11: {"field_no":"4"}

Sheet stat_log
A1: ts | B1: user_id | C1: source_type | D1: event_type | E1: action | F1: step | G1: label | H1: message_text | I1: postback_data | J1: process_ms | K1: extra_json | L1: date_int
A2: 46010.531 | D2: system | E2: doPost_events | F2: doPost | G2: events_count | K2: {"count":1} | L2: {=IF(A2:A684="","",INT(A2:A684))} -> 46010
A3: 46010.531 | B3: Ua636ab14081b483636896549d2026398 | C3: user | D3: postback | E3: restart_search_every_slot | F3: router | G3: postback_router | I3: action=restart_search_every_slot | K3: {"action":"restart_search_every_slot"} | L3: 46010
A4: 46010.531 | C4: system | D4: system | E4: perf | F4: handlePostback_ | G4: handlePostback_ | J4: 565 | K4: {"action":"restart_search_every_slot"} | L4: 46010
A5: 46010.531 | C5: system | D5: system | E5: perf | F5: doPost | G5: doPost | J5: 1362 | K5: {} | L5: 46010
A6: 46010.531 | D6: system | E6: doPost_events | F6: doPost | G6: events_count | K6: {"count":1} | L6: 46010
A7: 46010.531 | B7: Ua636ab14081b483636896549d2026398 | C7: user | D7: postback | E7: set_date_search_every_slot | F7: router | G7: postback_router | I7: action=set_date_search_every_slot | K7: {"action":"set_date_search_every_slot"} | L7: 46010
A8: 46010.531 | C8: system | D8: system | E8: perf | F8: handlePostback_ | G8: handlePostback_ | J8: 605 | K8: {"action":"set_date_search_every_slot"} | L8: 46010
A9: 46010.531 | C9: system | D9: system | E9: perf | F9: doPost | G9: doPost | J9: 1364 | K9: {} | L9: 46010
A10: 46010.531 | D10: system | E10: doPost_events | F10: doPost | G10: events_count | K10: {"count":1} | L10: 46010
A11: 46010.531 | B11: Ua636ab14081b483636896549d2026398 | C11: user | D11: postback | E11: pick_duration_search_every_slot | F11: router | G11: postback_router | I11: action=pick_duration_search_every_slot&date=2025-12-18&duration=60 | K11: {"action":"pick_duration_search_every_slot","date":"2025-12-18","duration":"60"} | L11: 46010
A12: 46010.532 | C12: system | D12: system | E12: perf | F12: handlePostback_ | G12: handlePostback_ | J12: 7122 | K12: {"action":"pick_duration_search_every_slot"} | L12: 46010
A13: 46010.532 | C13: system | D13: system | E13: perf | F13: doPost | G13: doPost | J13: 7987 | K13: {} | L13: 46010
A14: 46010.533 | D14: system | E14: doPost_events | F14: doPost | G14: events_count | K14: {"count":1} | L14: 46010
A15: 46010.533 | B15: Ufa0c1c6146fa747b4182cf3ca037c939 | C15: user | D15: message | E15: message_ignored | F15: general | G15: ignored_text | H15: เคร | L15: 46010
A16: 46010.533 | C16: system | D16: system | E16: perf | F16: handleMessage_ | G16: handleMessage_ | J16: 299 | K16: {"text":"เคร","ignored":true} | L16: 46010
A17: 46010.533 | C17: system | D17: system | E17: perf | F17: doPost | G17: doPost | J17: 1088 | K17: {} | L17: 46010
A18: 46010.719 | D18: system | E18: doPost_events | F18: doPost | G18: events_count | K18: {"count":1} | L18: 46010
A19: 46010.719 | B19: Ub2792da9d47050a2d6ada443a66e2282 | C19: user | D19: message | E19: search_time_menu_message | F19: search_time | G19: open_choice | H19: ค้นหาเวลา | L19: 46010
A20: 46010.719 | C20: system | D20: system | E20: perf | F20: handleMessage_ | G20: handleMessage_ | J20: 1354 | K20: {"text":"ค้นหาเวลา"} | L20: 46010
A21: 46010.719 | C21: system | D21: system | E21: perf | F21: doPost | G21: doPost | J21: 2945 | K21: {} | L21: 46010
A22: 46010.719 | D22: system | E22: doPost_events | F22: doPost | G22: events_count | K22: {"count":1} | L22: 46010
A23: 46010.719 | B23: Ub2792da9d47050a2d6ada443a66e2282 | C23: user | D23: postback | E23: choose_search_mode | F23: router | G23: postback_router | I23: action=choose_search_mode&mode=all | K23: {"action":"choose_search_mode","mode":"all"} | L23: 46010
A24: 46010.719 | B24: Ub2792da9d47050a2d6ada443a66e2282 | C24: user | D24: postback | E24: choose_search_mode | F24: search_time | G24: all | I24: action=choose_search_mode&mode=all | K24: {"action":"choose_search_mode","mode":"all"} | L24: 46010
A25: 46010.719 | C25: system | D25: system | E25: perf | F25: handlePostback_ | G25: handlePostback_ | J25: 975 | K25: {"action":"choose_search_mode"} | L25: 46010
A26: 46010.719 | C26: system | D26: system | E26: perf | F26: doPost | G26: doPost | J26: 2150 | K26: {} | L26: 46010
A27: 46010.719 | D27: system | E27: doPost_events | F27: doPost | G27: events_count | K27: {"count":1} | L27: 46010
A28: 46010.719 | B28: Ub2792da9d47050a2d6ada443a66e2282 | C28: user | D28: postback | E28: pick_date_search_every_slot | F28: router | G28: postback_router | I28: action=pick_date_search_every_slot&date_mode=today | K28: {"action":"pick_date_search_every_slot","date_mode":"today"} | L28: 46010
A29: 46010.719 | C29: system | D29: system | E29: perf | F29: handlePostback_ | G29: handlePostback_ | J29: 742 | K29: {"action":"pick_date_search_every_slot"} | L29: 46010
A30: 46010.719 | C30: system | D30: system | E30: perf | F30: doPost | G30: doPost | J30: 1312 | K30: {} | L30: 46010
A31: 46010.719 | D31: system | E31: doPost_events | F31: doPost | G31: events_count | K31: {"count":1} | L31: 46010
A32: 46010.719 | B32: Ub2792da9d47050a2d6ada443a66e2282 | C32: user | D32: postback | E32: pick_duration_search_every_slot | F32: router | G32: postback_router | I32: action=pick_duration_search_every_slot&date=2025-12-19&duration=60 | K32: {"action":"pick_duration_search_every_slot","date":"2025-12-19","duration":"60"} | L32: 46010
A33: 46010.719 | C33: system | D33: system | E33: perf | F33: handlePostback_ | G33: handlePostback_ | J33: 5875 | K33: {"action":"pick_duration_search_every_slot"} | L33: 46010
A34: 46010.719 | C34: system | D34: system | E34: perf | F34: doPost | G34: doPost | J34: 7222 | K34: {} | L34: 46010
A35: 46011.635 | D35: system | E35: doPost_events | F35: doPost | G35: events_count | K35: {"count":1} | L35: 46011
A36: 46011.635 | B36: U5d4f84131d821f14788b0299e8d470c2 | C36: user | D36: message | E36: search_time_menu_message | F36: search_time | G36: open_choice | H36: ค้นหาเวลา | L36: 46011
A37: 46011.635 | C37: system | D37: system | E37: perf | F37: handleMessage_ | G37: handleMessage_ | J37: 862 | K37: {"text":"ค้นหาเวลา"} | L37: 46011
A38: 46011.636 | C38: system | D38: system | E38: perf | F38: doPost | G38: doPost | J38: 2632 | K38: {} | L38: 46011
A39: 46011.636 | D39: system | E39: doPost_events | F39: doPost | G39: events_count | K39: {"count":1} | L39: 46011
A40: 46011.636 | B40: U5d4f84131d821f14788b0299e8d470c2 | C40: user | D40: postback | E40: choose_search_mode | F40: router | G40: postback_router | I40: action=choose_search_mode&mode=all | K40: {"action":"choose_search_mode","mode":"all"} | L40: 46011
...

Sheet stat_daily
A1: Date | B1: starts | C1: available | D1: unavailable | E1: change_time | F1: total_events | G1: avg_ms | H1: errors
A2: =IFERROR(__xludf.DUMMYFUNCTION("SORT( UNIQUE( FILTER( INT(stat_log!A2:A1000), stat_log!A2:A1000<>"""", INT(stat_log!A2:A1000)>1 ) ), 1,TRUE ) "),46010.0) -> 46010 | B2: {=IF(A2:A1000="","", COUNTIFS(INT(stat_log!A:A),A2:A1000, stat_log!E:E,"choose_search_mode") )} -> 2 | C2: {=IF(A2:A1000="","", COUNTIFS(INT(stat_log!A:A),A2:A1000, stat_log!E:E,"booking_result_available") )} -> 0 | D2: {=IF(A2:A1000="","", COUNTIFS(INT(stat_log!A:A),A2:A1000, stat_log!E:E,"booking_result_unavailable") )} -> 0 | E2: {=IF(A2:A1000="","", COUNTIFS(INT(stat_log!A:A),A2:A1000, stat_log!E:E,"booking_change_time") )} -> 0 | F2: {=IF(A2:A1000="","",COUNTIFS(INT(stat_log!A:A),A2:A1000))} -> 33 | G2: {=IF(A2:A1000="","",IFERROR( AVERAGEIF(INT(stat_log!A:A),A2:A1000,stat_log!J:J) ,""))} -> 2685.4375 | H2: {=IF(A2:A1000="","",COUNTIFS(INT(stat_log!A:A),A2:A1000,stat_log!E:E,"*error*")+COUNTIFS(INT(stat_log!A:A),A2:A1000,stat_log!E:E,"*invalid*")+COUNTIFS(INT(stat_log!A:A),A2:A1000,stat_log!E:E,"*exception*"))} -> 0
A3: =IFERROR(__xludf.DUMMYFUNCTION("""COMPUTED_VALUE"""),46011.0) -> 46011 | B3: 2 | C3: 0 | D3: 0 | E3: 0 | F3: 40 | G3: 2685.4375 | H3: 0
A4: =IFERROR(__xludf.DUMMYFUNCTION("""COMPUTED_VALUE"""),46012.0) -> 46012 | B4: 2 | C4: 0 | D4: 0 | E4: 0 | F4: 38 | G4: 2685.4375 | H4: 0
A5: =IFERROR(__xludf.DUMMYFUNCTION("""COMPUTED_VALUE"""),46013.0) -> 46013 | B5: 0 | C5: 0 | D5: 0 | E5: 0 | F5: 11 | G5: 2685.4375 | H5: 0
A6: =IFERROR(__xludf.DUMMYFUNCTION("""COMPUTED_VALUE"""),46014.0) -> 46014 | B6: 0 | C6: 0 | D6: 0 | E6: 0 | F6: 4 | G6: 2685.4375 | H6: 0
A7: =IFERROR(__xludf.DUMMYFUNCTION("""COMPUTED_VALUE"""),46015.0) -> 46015 | B7: 2 | C7: 1 | D7: 1 | E7: 1 | F7: 57 | G7: 2685.4375 | H7: 0
A8: =IFERROR(__xludf.DUMMYFUNCTION("""COMPUTED_VALUE"""),46017.0) -> 46017 | B8: 0 | C8: 0 | D8: 0 | E8: 0 | F8: 14 | G8: 2685.4375 | H8: 0
A9: =IFERROR(__xludf.DUMMYFUNCTION("""COMPUTED_VALUE"""),46018.0) -> 46018 | B9: 2 | C9: 0 | D9: 0 | E9: 0 | F9: 20 | G9: 2685.4375 | H9: 0
A10: =IFERROR(__xludf.DUMMYFUNCTION("""COMPUTED_VALUE"""),46019.0) -> 46019 | B10: 0 | C10: 0 | D10: 0 | E10: 0 | F10: 3 | G10: 2685.4375 | H10: 0
A11: =IFERROR(__xludf.DUMMYFUNCTION("""COMPUTED_VALUE"""),46020.0) -> 46020 | B11: 2 | C11: 0 | D11: 0 | E11: 0 | F11: 37 | G11: 2685.4375 | H11: 0
A12: =IFERROR(__xludf.DUMMYFUNCTION("""COMPUTED_VALUE"""),46021.0) -> 46021 | B12: 0 | C12: 0 | D12: 0 | E12: 0 | F12: 11 | G12: 2685.4375 | H12: 0
A13: =IFERROR(__xludf.DUMMYFUNCTION("""COMPUTED_VALUE"""),46025.0) -> 46025 | B13: 6 | C13: 0 | D13: 1 | E13: 0 | F13: 96 | G13: 2685.4375 | H13: 0
A14: =IFERROR(__xludf.DUMMYFUNCTION("""COMPUTED_VALUE"""),46026.0) -> 46026 | B14: 0 | C14: 0 | D14: 0 | E14: 0 | F14: 3 | G14: 2685.4375 | H14: 0
A15: =IFERROR(__xludf.DUMMYFUNCTION("""COMPUTED_VALUE"""),46028.0) -> 46028 | B15: 0 | C15: 0 | D15: 0 | E15: 0 | F15: 24 | G15: 2685.4375 | H15: 0
A16: =IFERROR(__xludf.DUMMYFUNCTION("""COMPUTED_VALUE"""),46029.0) -> 46029 | B16: 0 | C16: 0 | D16: 0 | E16: 0 | F16: 12 | G16: 2685.4375 | H16: 0
A17: =IFERROR(__xludf.DUMMYFUNCTION("""COMPUTED_VALUE"""),46030.0) -> 46030 | B17: 0 | C17: 0 | D17: 0 | E17: 0 | F17: 19 | G17: 2685.4375 | H17: 0
A18: =IFERROR(__xludf.DUMMYFUNCTION("""COMPUTED_VALUE"""),46031.0) -> 46031 | B18: 0 | C18: 0 | D18: 0 | E18: 0 | F18: 12 | G18: 2685.4375 | H18: 0
A19: =IFERROR(__xludf.DUMMYFUNCTION("""COMPUTED_VALUE"""),46032.0) -> 46032 | B19: 0 | C19: 0 | D19: 0 | E19: 0 | F19: 10 | G19: 2685.4375 | H19: 0
A20: =IFERROR(__xludf.DUMMYFUNCTION("""COMPUTED_VALUE"""),46033.0) -> 46033 | B20: 0 | C20: 0 | D20: 0 | E20: 0 | F20: 3 | G20: 2685.4375 | H20: 0
A21: =IFERROR(__xludf.DUMMYFUNCTION("""COMPUTED_VALUE"""),46034.0) -> 46034 | B21: 0 | C21: 0 | D21: 0 | E21: 0 | F21: 16 | G21: 2685.4375 | H21: 0
A22: =IFERROR(__xludf.DUMMYFUNCTION("""COMPUTED_VALUE"""),46035.0) -> 46035 | B22: 8 | C22: 0 | D22: 1 | E22: 1 | F22: 104 | G22: 2685.4375 | H22: 0
A23: =IFERROR(__xludf.DUMMYFUNCTION("""COMPUTED_VALUE"""),46036.0) -> 46036 | B23: 2 | C23: 0 | D23: 0 | E23: 0 | F23: 92 | G23: 2685.4375 | H23: 0
A24: =IFERROR(__xludf.DUMMYFUNCTION("""COMPUTED_VALUE"""),46037.0) -> 46037 | B24: 0 | C24: 0 | D24: 0 | E24: 0 | F24: 24 | G24: 2685.4375 | H24: 0

Sheet stat_funnel
A1: Date | B1: start_users | C1: select_date_users | D1: select_time_users | E1: select_duration_users | F1: select_field_users | G1: result_users | H1: =IFERROR(__xludf.DUMMYFUNCTION("COUNTUNIQUEIFS(stat_log!B:B, stat_log!L:L, INT(DATE(2025,12,24)), stat_log!E:E, ""choose_search_mode"") "),1.0) -> 1 | L1: date_int
A2: =IFERROR(__xludf.DUMMYFUNCTION("SORT(UNIQUE(FILTER(stat_log!L2:L1000, stat_log!L2:L1000<>"""")),1,TRUE) "),46010.0) -> 46010 | B2: =IFERROR(__xludf.DUMMYFUNCTION("ARRAYFORMULA(IF(A2:A1000="""","""", COUNTUNIQUEIFS(stat_log!B:B, stat_log!L:L, A2:A1000, stat_log!E:E, ""choose_search_mode"") )) "),1.0) -> 1 | C2: =IFERROR(__xludf.DUMMYFUNCTION("ARRAYFORMULA(IF(A2:A1000="""","""", COUNTUNIQUEIFS(stat_log!B:B, stat_log!L:L, A2:A1000, stat_log!E:E, ""booking_select_date"") +COUNTUNIQUEIFS(stat_log!B:B, stat_log!L:L, A2:A1000, stat_log!E:E, ""selectDate"") )) "),0.0) -> 0 | D2: =IFERROR(__xludf.DUMMYFUNCTION("ARRAYFORMULA(IF(A2:A1000="""","""", COUNTUNIQUEIFS(stat_log!B:B, stat_log!L:L, A2:A1000, stat_log!E:E, ""booking_select_time"") +COUNTUNIQUEIFS(stat_log!B:B, stat_log!L:L, A2:A1000, stat_log!E:E, ""selectTime"") )) "),0.0) -> 0 | E2: =IFERROR(__xludf.DUMMYFUNCTION("ARRAYFORMULA(IF(A2:A1000="""","""", COUNTUNIQUEIFS(stat_log!B:B, stat_log!L:L, A2:A1000, stat_log!E:E, ""booking_select_duration"") +COUNTUNIQUEIFS(stat_log!B:B, stat_log!L:L, A2:A1000, stat_log!E:E, ""selectDuration"") +COUNTUNIQUEIFS(stat_log!B:B, s"&"tat_log!L:L, A2:A1000, stat_log!E:E, ""pick_duration_search_every_slot"") )) "),2.0) -> 2 | F2: =IFERROR(__xludf.DUMMYFUNCTION("ARRAYFORMULA(IF(A2:A1000="""","""", COUNTUNIQUEIFS(stat_log!B:B, stat_log!L:L, A2:A1000, stat_log!E:E, ""booking_select_field"") +COUNTUNIQUEIFS(stat_log!B:B, stat_log!L:L, A2:A1000, stat_log!E:E, ""selectField"") )) "),0.0) -> 0 | G2: =IFERROR(__xludf.DUMMYFUNCTION("ARRAYFORMULA(IF(A2:A1000="""","""", COUNTUNIQUEIFS(stat_log!B:B, stat_log!L:L, A2:A1000, stat_log!E:E, ""booking_result_available"") +COUNTUNIQUEIFS(stat_log!B:B, stat_log!L:L, A2:A1000, stat_log!E:E, ""booking_result_unavailable"") )) "),0.0) -> 0 | H2: =COUNTIFS(stat_log!L:L, A2) -> 33 | L2: {=IF(A2:A1000="","",INT(A2:A1000))} -> 46010
A3: =IFERROR(__xludf.DUMMYFUNCTION("""COMPUTED_VALUE"""),46011.0) -> 46011 | B3: =IFERROR(__xludf.DUMMYFUNCTION("""COMPUTED_VALUE"""),1.0) -> 1 | C3: =IFERROR(__xludf.DUMMYFUNCTION("""COMPUTED_VALUE"""),0.0) -> 0 | D3: =IFERROR(__xludf.DUMMYFUNCTION("""COMPUTED_VALUE"""),0.0) -> 0 | E3: =IFERROR(__xludf.DUMMYFUNCTION("""COMPUTED_VALUE"""),2.0) -> 2 | F3: =IFERROR(__xludf.DUMMYFUNCTION("""COMPUTED_VALUE"""),0.0) -> 0 | G3: =IFERROR(__xludf.DUMMYFUNCTION("""COMPUTED_VALUE"""),0.0) -> 0 | L3: 46011
A4: =IFERROR(__xludf.DUMMYFUNCTION("""COMPUTED_VALUE"""),46012.0) -> 46012 | B4: =IFERROR(__xludf.DUMMYFUNCTION("""COMPUTED_VALUE"""),1.0) -> 1 | C4: =IFERROR(__xludf.DUMMYFUNCTION("""COMPUTED_VALUE"""),0.0) -> 0 | D4: =IFERROR(__xludf.DUMMYFUNCTION("""COMPUTED_VALUE"""),0.0) -> 0 | E4: =IFERROR(__xludf.DUMMYFUNCTION("""COMPUTED_VALUE"""),2.0) -> 2 | F4: =IFERROR(__xludf.DUMMYFUNCTION("""COMPUTED_VALUE"""),0.0) -> 0 | G4: =IFERROR(__xludf.DUMMYFUNCTION("""COMPUTED_VALUE"""),0.0) -> 0 | L4: 46012
A5: =IFERROR(__xludf.DUMMYFUNCTION("""COMPUTED_VALUE"""),46013.0) -> 46013 | B5: =IFERROR(__xludf.DUMMYFUNCTION("""COMPUTED_VALUE"""),1.0) -> 1 | C5: =IFERROR(__xludf.DUMMYFUNCTION("""COMPUTED_VALUE"""),0.0) -> 0 | D5: =IFERROR(__xludf.DUMMYFUNCTION("""COMPUTED_VALUE"""),0.0) -> 0 | E5: =IFERROR(__xludf.DUMMYFUNCTION("""COMPUTED_VALUE"""),2.0) -> 2 | F5: =IFERROR(__xludf.DUMMYFUNCTION("""COMPUTED_VALUE"""),0.0) -> 0 | G5: =IFERROR(__xludf.DUMMYFUNCTION("""COMPUTED_VALUE"""),0.0) -> 0 | L5: 46013
A6: =IFERROR(__xludf.DUMMYFUNCTION("""COMPUTED_VALUE"""),46014.0) -> 46014 | B6: =IFERROR(__xludf.DUMMYFUNCTION("""COMPUTED_VALUE"""),1.0) -> 1 | C6: =IFERROR(__xludf.DUMMYFUNCTION("""COMPUTED_VALUE"""),0.0) -> 0 | D6: =IFERROR(__xludf.DUMMYFUNCTION("""COMPUTED_VALUE"""),0.0) -> 0 | E6: =IFERROR(__xludf.DUMMYFUNCTION("""COMPUTED_VALUE"""),2.0) -> 2 | F6: =IFERROR(__xludf.DUMMYFUNCTION("""COMPUTED_VALUE"""),0.0) -> 0 | G6: =IFERROR(__xludf.DUMMYFUNCTION("""COMPUTED_VALUE"""),0.0) -> 0 | L6: 46014
A7: =IFERROR(__xludf.DUMMYFUNCTION("""COMPUTED_VALUE"""),46015.0) -> 46015 | B7: =IFERROR(__xludf.DUMMYFUNCTION("""COMPUTED_VALUE"""),1.0) -> 1 | C7: =IFERROR(__xludf.DUMMYFUNCTION("""COMPUTED_VALUE"""),0.0) -> 0 | D7: =IFERROR(__xludf.DUMMYFUNCTION("""COMPUTED_VALUE"""),0.0) -> 0 | E7: =IFERROR(__xludf.DUMMYFUNCTION("""COMPUTED_VALUE"""),2.0) -> 2 | F7: =IFERROR(__xludf.DUMMYFUNCTION("""COMPUTED_VALUE"""),0.0) -> 0 | G7: =IFERROR(__xludf.DUMMYFUNCTION("""COMPUTED_VALUE"""),0.0) -> 0 | L7: 46015
A8: =IFERROR(__xludf.DUMMYFUNCTION("""COMPUTED_VALUE"""),46017.0) -> 46017 | B8: =IFERROR(__xludf.DUMMYFUNCTION("""COMPUTED_VALUE"""),1.0) -> 1 | C8: =IFERROR(__xludf.DUMMYFUNCTION("""COMPUTED_VALUE"""),0.0) -> 0 | D8: =IFERROR(__xludf.DUMMYFUNCTION("""COMPUTED_VALUE"""),0.0) -> 0 | E8: =IFERROR(__xludf.DUMMYFUNCTION("""COMPUTED_VALUE"""),2.0) -> 2 | F8: =IFERROR(__xludf.DUMMYFUNCTION("""COMPUTED_VALUE"""),0.0) -> 0 | G8: =IFERROR(__xludf.DUMMYFUNCTION("""COMPUTED_VALUE"""),0.0) -> 0 | L8: 46017
A9: =IFERROR(__xludf.DUMMYFUNCTION("""COMPUTED_VALUE"""),46018.0) -> 46018 | B9: =IFERROR(__xludf.DUMMYFUNCTION("""COMPUTED_VALUE"""),1.0) -> 1 | C9: =IFERROR(__xludf.DUMMYFUNCTION("""COMPUTED_VALUE"""),0.0) -> 0 | D9: =IFERROR(__xludf.DUMMYFUNCTION("""COMPUTED_VALUE"""),0.0) -> 0 | E9: =IFERROR(__xludf.DUMMYFUNCTION("""COMPUTED_VALUE"""),2.0) -> 2 | F9: =IFERROR(__xludf.DUMMYFUNCTION("""COMPUTED_VALUE"""),0.0) -> 0 | G9: =IFERROR(__xludf.DUMMYFUNCTION("""COMPUTED_VALUE"""),0.0) -> 0 | L9: 46018
A10: =IFERROR(__xludf.DUMMYFUNCTION("""COMPUTED_VALUE"""),46019.0) -> 46019 | B10: =IFERROR(__xludf.DUMMYFUNCTION("""COMPUTED_VALUE"""),1.0) -> 1 | C10: =IFERROR(__xludf.DUMMYFUNCTION("""COMPUTED_VALUE"""),0.0) -> 0 | D10: =IFERROR(__xludf.DUMMYFUNCTION("""COMPUTED_VALUE"""),0.0) -> 0 | E10: =IFERROR(__xludf.DUMMYFUNCTION("""COMPUTED_VALUE"""),2.0) -> 2 | F10: =IFERROR(__xludf.DUMMYFUNCTION("""COMPUTED_VALUE"""),0.0) -> 0 | G10: =IFERROR(__xludf.DUMMYFUNCTION("""COMPUTED_VALUE"""),0.0) -> 0 | L10: 46019
A11: =IFERROR(__xludf.DUMMYFUNCTION("""COMPUTED_VALUE"""),46020.0) -> 46020 | B11: =IFERROR(__xludf.DUMMYFUNCTION("""COMPUTED_VALUE"""),1.0) -> 1 | C11: =IFERROR(__xludf.DUMMYFUNCTION("""COMPUTED_VALUE"""),0.0) -> 0 | D11: =IFERROR(__xludf.DUMMYFUNCTION("""COMPUTED_VALUE"""),0.0) -> 0 | E11: =IFERROR(__xludf.DUMMYFUNCTION("""COMPUTED_VALUE"""),2.0) -> 2 | F11: =IFERROR(__xludf.DUMMYFUNCTION("""COMPUTED_VALUE"""),0.0) -> 0 | G11: =IFERROR(__xludf.DUMMYFUNCTION("""COMPUTED_VALUE"""),0.0) -> 0 | L11: 46020
A12: =IFERROR(__xludf.DUMMYFUNCTION("""COMPUTED_VALUE"""),46021.0) -> 46021 | B12: =IFERROR(__xludf.DUMMYFUNCTION("""COMPUTED_VALUE"""),1.0) -> 1 | C12: =IFERROR(__xludf.DUMMYFUNCTION("""COMPUTED_VALUE"""),0.0) -> 0 | D12: =IFERROR(__xludf.DUMMYFUNCTION("""COMPUTED_VALUE"""),0.0) -> 0 | E12: =IFERROR(__xludf.DUMMYFUNCTION("""COMPUTED_VALUE"""),2.0) -> 2 | F12: =IFERROR(__xludf.DUMMYFUNCTION("""COMPUTED_VALUE"""),0.0) -> 0 | G12: =IFERROR(__xludf.DUMMYFUNCTION("""COMPUTED_VALUE"""),0.0) -> 0 | L12: 46021
A13: =IFERROR(__xludf.DUMMYFUNCTION("""COMPUTED_VALUE"""),46025.0) -> 46025 | B13: =IFERROR(__xludf.DUMMYFUNCTION("""COMPUTED_VALUE"""),1.0) -> 1 | C13: =IFERROR(__xludf.DUMMYFUNCTION("""COMPUTED_VALUE"""),0.0) -> 0 | D13: =IFERROR(__xludf.DUMMYFUNCTION("""COMPUTED_VALUE"""),0.0) -> 0 | E13: =IFERROR(__xludf.DUMMYFUNCTION("""COMPUTED_VALUE"""),2.0) -> 2 | F13: =IFERROR(__xludf.DUMMYFUNCTION("""COMPUTED_VALUE"""),0.0) -> 0 | G13: =IFERROR(__xludf.DUMMYFUNCTION("""COMPUTED_VALUE"""),0.0) -> 0 | L13: 46025
A14: =IFERROR(__xludf.DUMMYFUNCTION("""COMPUTED_VALUE"""),46026.0) -> 46026 | B14: =IFERROR(__xludf.DUMMYFUNCTION("""COMPUTED_VALUE"""),1.0) -> 1 | C14: =IFERROR(__xludf.DUMMYFUNCTION("""COMPUTED_VALUE"""),0.0) -> 0 | D14: =IFERROR(__xludf.DUMMYFUNCTION("""COMPUTED_VALUE"""),0.0) -> 0 | E14: =IFERROR(__xludf.DUMMYFUNCTION("""COMPUTED_VALUE"""),2.0) -> 2 | F14: =IFERROR(__xludf.DUMMYFUNCTION("""COMPUTED_VALUE"""),0.0) -> 0 | G14: =IFERROR(__xludf.DUMMYFUNCTION("""COMPUTED_VALUE"""),0.0) -> 0 | L14: 46026
A15: =IFERROR(__xludf.DUMMYFUNCTION("""COMPUTED_VALUE"""),46028.0) -> 46028 | B15: =IFERROR(__xludf.DUMMYFUNCTION("""COMPUTED_VALUE"""),1.0) -> 1 | C15: =IFERROR(__xludf.DUMMYFUNCTION("""COMPUTED_VALUE"""),0.0) -> 0 | D15: =IFERROR(__xludf.DUMMYFUNCTION("""COMPUTED_VALUE"""),0.0) -> 0 | E15: =IFERROR(__xludf.DUMMYFUNCTION("""COMPUTED_VALUE"""),2.0) -> 2 | F15: =IFERROR(__xludf.DUMMYFUNCTION("""COMPUTED_VALUE"""),0.0) -> 0 | G15: =IFERROR(__xludf.DUMMYFUNCTION("""COMPUTED_VALUE"""),0.0) -> 0 | L15: 46028
A16: =IFERROR(__xludf.DUMMYFUNCTION("""COMPUTED_VALUE"""),46029.0) -> 46029 | B16: =IFERROR(__xludf.DUMMYFUNCTION("""COMPUTED_VALUE"""),1.0) -> 1 | C16: =IFERROR(__xludf.DUMMYFUNCTION("""COMPUTED_VALUE"""),0.0) -> 0 | D16: =IFERROR(__xludf.DUMMYFUNCTION("""COMPUTED_VALUE"""),0.0) -> 0 | E16: =IFERROR(__xludf.DUMMYFUNCTION("""COMPUTED_VALUE"""),2.0) -> 2 | F16: =IFERROR(__xludf.DUMMYFUNCTION("""COMPUTED_VALUE"""),0.0) -> 0 | G16: =IFERROR(__xludf.DUMMYFUNCTION("""COMPUTED_VALUE"""),0.0) -> 0 | L16: 46029
A17: =IFERROR(__xludf.DUMMYFUNCTION("""COMPUTED_VALUE"""),46030.0) -> 46030 | B17: =IFERROR(__xludf.DUMMYFUNCTION("""COMPUTED_VALUE"""),1.0) -> 1 | C17: =IFERROR(__xludf.DUMMYFUNCTION("""COMPUTED_VALUE"""),0.0) -> 0 | D17: =IFERROR(__xludf.DUMMYFUNCTION("""COMPUTED_VALUE"""),0.0) -> 0 | E17: =IFERROR(__xludf.DUMMYFUNCTION("""COMPUTED_VALUE"""),2.0) -> 2 | F17: =IFERROR(__xludf.DUMMYFUNCTION("""COMPUTED_VALUE"""),0.0) -> 0 | G17: =IFERROR(__xludf.DUMMYFUNCTION("""COMPUTED_VALUE"""),0.0) -> 0 | L17: 46030
A18: =IFERROR(__xludf.DUMMYFUNCTION("""COMPUTED_VALUE"""),46031.0) -> 46031 | B18: =IFERROR(__xludf.DUMMYFUNCTION("""COMPUTED_VALUE"""),1.0) -> 1 | C18: =IFERROR(__xludf.DUMMYFUNCTION("""COMPUTED_VALUE"""),0.0) -> 0 | D18: =IFERROR(__xludf.DUMMYFUNCTION("""COMPUTED_VALUE"""),0.0) -> 0 | E18: =IFERROR(__xludf.DUMMYFUNCTION("""COMPUTED_VALUE"""),2.0) -> 2 | F18: =IFERROR(__xludf.DUMMYFUNCTION("""COMPUTED_VALUE"""),0.0) -> 0 | G18: =IFERROR(__xludf.DUMMYFUNCTION("""COMPUTED_VALUE"""),0.0) -> 0 | L18: 46031
A19: =IFERROR(__xludf.DUMMYFUNCTION("""COMPUTED_VALUE"""),46032.0) -> 46032 | B19: =IFERROR(__xludf.DUMMYFUNCTION("""COMPUTED_VALUE"""),1.0) -> 1 | C19: =IFERROR(__xludf.DUMMYFUNCTION("""COMPUTED_VALUE"""),0.0) -> 0 | D19: =IFERROR(__xludf.DUMMYFUNCTION("""COMPUTED_VALUE"""),0.0) -> 0 | E19: =IFERROR(__xludf.DUMMYFUNCTION("""COMPUTED_VALUE"""),2.0) -> 2 | F19: =IFERROR(__xludf.DUMMYFUNCTION("""COMPUTED_VALUE"""),0.0) -> 0 | G19: =IFERROR(__xludf.DUMMYFUNCTION("""COMPUTED_VALUE"""),0.0) -> 0 | L19: 46032
A20: =IFERROR(__xludf.DUMMYFUNCTION("""COMPUTED_VALUE"""),46033.0) -> 46033 | B20: =IFERROR(__xludf.DUMMYFUNCTION("""COMPUTED_VALUE"""),1.0) -> 1 | C20: =IFERROR(__xludf.DUMMYFUNCTION("""COMPUTED_VALUE"""),0.0) -> 0 | D20: =IFERROR(__xludf.DUMMYFUNCTION("""COMPUTED_VALUE"""),0.0) -> 0 | E20: =IFERROR(__xludf.DUMMYFUNCTION("""COMPUTED_VALUE"""),2.0) -> 2 | F20: =IFERROR(__xludf.DUMMYFUNCTION("""COMPUTED_VALUE"""),0.0) -> 0 | G20: =IFERROR(__xludf.DUMMYFUNCTION("""COMPUTED_VALUE"""),0.0) -> 0 | L20: 46033
A21: =IFERROR(__xludf.DUMMYFUNCTION("""COMPUTED_VALUE"""),46034.0) -> 46034 | B21: =IFERROR(__xludf.DUMMYFUNCTION("""COMPUTED_VALUE"""),1.0) -> 1 | C21: =IFERROR(__xludf.DUMMYFUNCTION("""COMPUTED_VALUE"""),0.0) -> 0 | D21: =IFERROR(__xludf.DUMMYFUNCTION("""COMPUTED_VALUE"""),0.0) -> 0 | E21: =IFERROR(__xludf.DUMMYFUNCTION("""COMPUTED_VALUE"""),2.0) -> 2 | F21: =IFERROR(__xludf.DUMMYFUNCTION("""COMPUTED_VALUE"""),0.0) -> 0 | G21: =IFERROR(__xludf.DUMMYFUNCTION("""COMPUTED_VALUE"""),0.0) -> 0 | L21: 46034
A22: =IFERROR(__xludf.DUMMYFUNCTION("""COMPUTED_VALUE"""),46035.0) -> 46035 | B22: =IFERROR(__xludf.DUMMYFUNCTION("""COMPUTED_VALUE"""),1.0) -> 1 | C22: =IFERROR(__xludf.DUMMYFUNCTION("""COMPUTED_VALUE"""),0.0) -> 0 | D22: =IFERROR(__xludf.DUMMYFUNCTION("""COMPUTED_VALUE"""),0.0) -> 0 | E22: =IFERROR(__xludf.DUMMYFUNCTION("""COMPUTED_VALUE"""),2.0) -> 2 | F22: =IFERROR(__xludf.DUMMYFUNCTION("""COMPUTED_VALUE"""),0.0) -> 0 | G22: =IFERROR(__xludf.DUMMYFUNCTION("""COMPUTED_VALUE"""),0.0) -> 0 | L22: 46035
A23: =IFERROR(__xludf.DUMMYFUNCTION("""COMPUTED_VALUE"""),46036.0) -> 46036 | B23: =IFERROR(__xludf.DUMMYFUNCTION("""COMPUTED_VALUE"""),1.0) -> 1 | C23: =IFERROR(__xludf.DUMMYFUNCTION("""COMPUTED_VALUE"""),0.0) -> 0 | D23: =IFERROR(__xludf.DUMMYFUNCTION("""COMPUTED_VALUE"""),0.0) -> 0 | E23: =IFERROR(__xludf.DUMMYFUNCTION("""COMPUTED_VALUE"""),2.0) -> 2 | F23: =IFERROR(__xludf.DUMMYFUNCTION("""COMPUTED_VALUE"""),0.0) -> 0 | G23: =IFERROR(__xludf.DUMMYFUNCTION("""COMPUTED_VALUE"""),0.0) -> 0 | L23: 46036
A24: =IFERROR(__xludf.DUMMYFUNCTION("""COMPUTED_VALUE"""),46037.0) -> 46037 | B24: =IFERROR(__xludf.DUMMYFUNCTION("""COMPUTED_VALUE"""),1.0) -> 1 | C24: =IFERROR(__xludf.DUMMYFUNCTION("""COMPUTED_VALUE"""),0.0) -> 0 | D24: =IFERROR(__xludf.DUMMYFUNCTION("""COMPUTED_VALUE"""),0.0) -> 0 | E24: =IFERROR(__xludf.DUMMYFUNCTION("""COMPUTED_VALUE"""),2.0) -> 2 | F24: =IFERROR(__xludf.DUMMYFUNCTION("""COMPUTED_VALUE"""),0.0) -> 0 | G24: =IFERROR(__xludf.DUMMYFUNCTION("""COMPUTED_VALUE"""),0.0) -> 0 | L24: 46037
B25: =IFERROR(__xludf.DUMMYFUNCTION("""COMPUTED_VALUE"""),"") | C25: =IFERROR(__xludf.DUMMYFUNCTION("""COMPUTED_VALUE"""),"") | D25: =IFERROR(__xludf.DUMMYFUNCTION("""COMPUTED_VALUE"""),"") | E25: =IFERROR(__xludf.DUMMYFUNCTION("""COMPUTED_VALUE"""),"") | F25: =IFERROR(__xludf.DUMMYFUNCTION("""COMPUTED_VALUE"""),"") | G25: =IFERROR(__xludf.DUMMYFUNCTION("""COMPUTED_VALUE"""),"")
B26: =IFERROR(__xludf.DUMMYFUNCTION("""COMPUTED_VALUE"""),"") | C26: =IFERROR(__xludf.DUMMYFUNCTION("""COMPUTED_VALUE"""),"") | D26: =IFERROR(__xludf.DUMMYFUNCTION("""COMPUTED_VALUE"""),"") | E26: =IFERROR(__xludf.DUMMYFUNCTION("""COMPUTED_VALUE"""),"") | F26: =IFERROR(__xludf.DUMMYFUNCTION("""COMPUTED_VALUE"""),"") | G26: =IFERROR(__xludf.DUMMYFUNCTION("""COMPUTED_VALUE"""),"")
B27: =IFERROR(__xludf.DUMMYFUNCTION("""COMPUTED_VALUE"""),"") | C27: =IFERROR(__xludf.DUMMYFUNCTION("""COMPUTED_VALUE"""),"") | D27: =IFERROR(__xludf.DUMMYFUNCTION("""COMPUTED_VALUE"""),"") | E27: =IFERROR(__xludf.DUMMYFUNCTION("""COMPUTED_VALUE"""),"") | F27: =IFERROR(__xludf.DUMMYFUNCTION("""COMPUTED_VALUE"""),"") | G27: =IFERROR(__xludf.DUMMYFUNCTION("""COMPUTED_VALUE"""),"")
B28: =IFERROR(__xludf.DUMMYFUNCTION("""COMPUTED_VALUE"""),"") | C28: =IFERROR(__xludf.DUMMYFUNCTION("""COMPUTED_VALUE"""),"") | D28: =IFERROR(__xludf.DUMMYFUNCTION("""COMPUTED_VALUE"""),"") | E28: =IFERROR(__xludf.DUMMYFUNCTION("""COMPUTED_VALUE"""),"") | F28: =IFERROR(__xludf.DUMMYFUNCTION("""COMPUTED_VALUE"""),"") | G28: =IFERROR(__xludf.DUMMYFUNCTION("""COMPUTED_VALUE"""),"")
B29: =IFERROR(__xludf.DUMMYFUNCTION("""COMPUTED_VALUE"""),"") | C29: =IFERROR(__xludf.DUMMYFUNCTION("""COMPUTED_VALUE"""),"") | D29: =IFERROR(__xludf.DUMMYFUNCTION("""COMPUTED_VALUE"""),"") | E29: =IFERROR(__xludf.DUMMYFUNCTION("""COMPUTED_VALUE"""),"") | F29: =IFERROR(__xludf.DUMMYFUNCTION("""COMPUTED_VALUE"""),"") | G29: =IFERROR(__xludf.DUMMYFUNCTION("""COMPUTED_VALUE"""),"")
B30: =IFERROR(__xludf.DUMMYFUNCTION("""COMPUTED_VALUE"""),"") | C30: =IFERROR(__xludf.DUMMYFUNCTION("""COMPUTED_VALUE"""),"") | D30: =IFERROR(__xludf.DUMMYFUNCTION("""COMPUTED_VALUE"""),"") | E30: =IFERROR(__xludf.DUMMYFUNCTION("""COMPUTED_VALUE"""),"") | F30: =IFERROR(__xludf.DUMMYFUNCTION("""COMPUTED_VALUE"""),"") | G30: =IFERROR(__xludf.DUMMYFUNCTION("""COMPUTED_VALUE"""),"")
B31: =IFERROR(__xludf.DUMMYFUNCTION("""COMPUTED_VALUE"""),"") | C31: =IFERROR(__xludf.DUMMYFUNCTION("""COMPUTED_VALUE"""),"") | D31: =IFERROR(__xludf.DUMMYFUNCTION("""COMPUTED_VALUE"""),"") | E31: =IFERROR(__xludf.DUMMYFUNCTION("""COMPUTED_VALUE"""),"") | F31: =IFERROR(__xludf.DUMMYFUNCTION("""COMPUTED_VALUE"""),"") | G31: =IFERROR(__xludf.DUMMYFUNCTION("""COMPUTED_VALUE"""),"")
B32: =IFERROR(__xludf.DUMMYFUNCTION("""COMPUTED_VALUE"""),"") | C32: =IFERROR(__xludf.DUMMYFUNCTION("""COMPUTED_VALUE"""),"") | D32: =IFERROR(__xludf.DUMMYFUNCTION("""COMPUTED_VALUE"""),"") | E32: =IFERROR(__xludf.DUMMYFUNCTION("""COMPUTED_VALUE"""),"") | F32: =IFERROR(__xludf.DUMMYFUNCTION("""COMPUTED_VALUE"""),"") | G32: =IFERROR(__xludf.DUMMYFUNCTION("""COMPUTED_VALUE"""),"")
B33: =IFERROR(__xludf.DUMMYFUNCTION("""COMPUTED_VALUE"""),"") | C33: =IFERROR(__xludf.DUMMYFUNCTION("""COMPUTED_VALUE"""),"") | D33: =IFERROR(__xludf.DUMMYFUNCTION("""COMPUTED_VALUE"""),"") | E33: =IFERROR(__xludf.DUMMYFUNCTION("""COMPUTED_VALUE"""),"") | F33: =IFERROR(__xludf.DUMMYFUNCTION("""COMPUTED_VALUE"""),"") | G33: =IFERROR(__xludf.DUMMYFUNCTION("""COMPUTED_VALUE"""),"")
B34: =IFERROR(__xludf.DUMMYFUNCTION("""COMPUTED_VALUE"""),"") | C34: =IFERROR(__xludf.DUMMYFUNCTION("""COMPUTED_VALUE"""),"") | D34: =IFERROR(__xludf.DUMMYFUNCTION("""COMPUTED_VALUE"""),"") | E34: =IFERROR(__xludf.DUMMYFUNCTION("""COMPUTED_VALUE"""),"") | F34: =IFERROR(__xludf.DUMMYFUNCTION("""COMPUTED_VALUE"""),"") | G34: =IFERROR(__xludf.DUMMYFUNCTION("""COMPUTED_VALUE"""),"")
B35: =IFERROR(__xludf.DUMMYFUNCTION("""COMPUTED_VALUE"""),"") | C35: =IFERROR(__xludf.DUMMYFUNCTION("""COMPUTED_VALUE"""),"") | D35: =IFERROR(__xludf.DUMMYFUNCTION("""COMPUTED_VALUE"""),"") | E35: =IFERROR(__xludf.DUMMYFUNCTION("""COMPUTED_VALUE"""),"") | F35: =IFERROR(__xludf.DUMMYFUNCTION("""COMPUTED_VALUE"""),"") | G35: =IFERROR(__xludf.DUMMYFUNCTION("""COMPUTED_VALUE"""),"")
B36: =IFERROR(__xludf.DUMMYFUNCTION("""COMPUTED_VALUE"""),"") | C36: =IFERROR(__xludf.DUMMYFUNCTION("""COMPUTED_VALUE"""),"") | D36: =IFERROR(__xludf.DUMMYFUNCTION("""COMPUTED_VALUE"""),"") | E36: =IFERROR(__xludf.DUMMYFUNCTION("""COMPUTED_VALUE"""),"") | F36: =IFERROR(__xludf.DUMMYFUNCTION("""COMPUTED_VALUE"""),"") | G36: =IFERROR(__xludf.DUMMYFUNCTION("""COMPUTED_VALUE"""),"")
... B1000: =IFERROR(__xludf.DUMMYFUNCTION("""COMPUTED_VALUE"""),"") | C1000: =IFERROR(__xludf.DUMMYFUNCTION("""COMPUTED_VALUE"""),"") | D1000: =IFERROR(__xludf.DUMMYFUNCTION("""COMPUTED_VALUE"""),"") | E1000: =IFERROR(__xludf.DUMMYFUNCTION("""COMPUTED_VALUE"""),"") | F1000: =IFERROR(__xludf.DUMMYFUNCTION("""COMPUTED_VALUE"""),"") | G1000: =IFERROR(__xludf.DUMMYFUNCTION("""COMPUTED_VALUE"""),"")

Sheet stat_actions
